---
layout: post

title: "linux下巡风项目运行错误排查"
date: 2017-03-05 11:56:17 +0800

categories: post
tags: [ubuntu, mongodb]
---

最近看到了[同程安全](http://mp.weixin.qq.com/s/sFDY8vzonIW2gAcw0CCkzQ)的开源项目 - [巡风](https://github.com/ysrc/xunfeng), 感觉挺好玩的, 准备在自己的系统安装, 安装[官方教程](https://github.com/ysrc/xunfeng/blob/master/docs/install/Linux.md), 其中遇到一些问题, 记录下.

```shell
$ python2 Run.py
Traceback (most recent call last):
  File "Run.py", line 1, in <module>
    from views.View import app
  File "/path/to/xunfeng/views/__init__.py", line 12, in <module>
    app.config.get('DBUSERNAME'), app.config.get('DBPASSWORD'))
  File "/path/to/xunfeng/views/lib/Conn.py", line 13, in __init__
    self.coll.authenticate(username, password)
  File "/usr/local/lib/python2.7/dist-packages/pymongo/database.py", line 1048, in authenticate
    connect=True)
    ...
  File "/usr/local/lib/python2.7/dist-packages/pymongo/network.py", line 116, in command
    parse_write_concern_error=parse_write_concern_error)
  File "/usr/local/lib/python2.7/dist-packages/pymongo/helpers.py", line 210, in _check_command_response
    raise OperationFailure(msg % errmsg, code, response)
pymongo.errors.OperationFailure: Authentication failed.
```
修改mongo数据库 连接方式解决了 [^1]

![巡风]({{ site.url }}/assets/images/201703/05-01.png)

```shell
$ python2 Run.py                                                          1 ↵
Traceback (most recent call last):
  File "Run.py", line 1, in <module>
    from views.View import app
  File "/path/to/xunfeng/views/View.py", line 10, in <module>
    from lib.CreateExcel import *
  File "/path/to/xunfeng/views/lib/CreateExcel.py", line 3, in <module>
    import xlwt
ImportError: No module named xlwt
```
安装xlwt包 解决了, `$ sudo pip2 install xlwt`

```shell
$ python2 Run.py        
Traceback (most recent call last):
  File "Run.py", line 5, in <module>
    app.run(threaded=True, port=80,host='0.0.0.0')
  File "/usr/local/lib/python2.7/dist-packages/flask/app.py", line 841, in run
    run_simple(host, port, self, **options)
  File "/usr/local/lib/python2.7/dist-packages/werkzeug/serving.py", line 691, in run_simple
    s.bind((hostname, port))
  File "/usr/lib/python2.7/socket.py", line 228, in meth
    return getattr(self._sock,name)(*args)
socket.error: [Errno 13] Permission denied
```
直接使用sudo权限 解决了 [^2]

```shell
$ sudo python2 Run.py                                                     1 ↵
Traceback (most recent call last):
  File "Run.py", line 5, in <module>
    app.run(threaded=True, port=80,host='0.0.0.0')
  File "/usr/local/lib/python2.7/dist-packages/flask/app.py", line 841, in run
    run_simple(host, port, self, **options)
  File "/usr/local/lib/python2.7/dist-packages/werkzeug/serving.py", line 699, in run_simple
    s.listen(LISTEN_QUEUE)
  File "/usr/lib/python2.7/socket.py", line 228, in meth
    return getattr(self._sock,name)(*args)
socket.error: [Errno 98] Address already in use
```
将 run.py 的port 80 换成 800 即可. [^3]

```python
from views.View import app

if __name__ == '__main__':
    app.debug = True
    app.run(threaded=True, port=800,host='0.0.0.0')
```

可以运行了.

```shell
$ sudo python2 Run.py
 * Running on http://0.0.0.0:800/ (Press CTRL+C to quit)
 * Restarting with stat
 * Debugger is active!
 * Debugger pin code: 290-209-200
```

![巡风]({{ site.url }}/assets/images/201703/05-02.png)

---

[^1]: [pymongo auth failed in python script](http://stackoverflow.com/questions/40346767/pymongo-auth-failed-in-python-script) && [README mongodb添加认证处少了db.auth('username','password')](https://github.com/ysrc/xunfeng/issues/56)

[^2]: [Permission denied when creating a fake email server](http://stackoverflow.com/questions/25709716/socket-error-errno-13-permission-denied-when-creating-a-fake-email-server)

[^3]: 其他解决方案 [Address already in use](http://stackoverflow.com/questions/4465959/python-errno-98-address-already-in-use)
